<mujoco model="ant">
  <compiler inertiafromgeom="true" angle="degree" coordinate="local" />
  <size njmax="5000" nconmax="3500"></size>
  <option timestep="0.01" integrator="RK4" />
  <custom>
    <numeric name="init_qpos" data="0.0 0.0 0.55 1.0 0.0 0.0 0.0 0.0 1.0 0.0 -1.0 0.0 -1.0 0.0 1.0" />
  </custom>
  <default>
    <joint limited="true" armature="1" damping="1" />
    <geom condim="3" conaffinity="0" margin="0.01" friction="1 0.5 0.5" solref=".02 1" solimp=".8 .8 .01" rgba="0.8 0.6 0.4 1" density="5.0" />
  </default>
  <asset>
    <texture type="skybox" builtin="gradient" width="100" height="100" rgb1="1 1 1" rgb2="0 0 0" />
    <texture name="texgeom" type="cube" builtin="flat" mark="cross" width="127" height="1278" rgb1="0.8 0.6 0.4" rgb2="0.8 0.6 0.4" markrgb="1 1 1" random="0.01" />
    <texture name="texplane" type="2d" builtin="checker" rgb1="0.2 0.3 0.4" rgb2="0.1 0.2 0.3" width="100" height="100" />
    <material name='MatPlane' texture="texplane" shininess="1" texrepeat="60 60" specular="1"  reflectance="0.0" />
    <material name='geom' texture="texgeom" texuniform="true" />
  </asset>
  <worldbody>
    <light directional="true" cutoff="100" exponent="1" diffuse="1 1 1" specular=".1 .1 .1" pos="0 0 1.3" dir="-0 0 -1.3" />
    <!-- <include file="shared.xml"></include> -->
    <geom name='floor' pos='0 0 0' size='40 40 40' type='plane' conaffinity='1' rgba='0.8 0.9 0.8 1' condim='3' material='MatPlane' />
    <body name="torso" pos="0 0 0.75">
      <geom name="torso_geom" type="sphere" size="0.4" pos="0 0 0" rgba="0.3 0.9 0.5 1"/>
      <joint name="root" type="free" limited="false" pos="0 0 0" axis="0 0 1" margin="0.01" armature="0" damping="0" />
      <body name="front_left_leg" pos="0 0 0">
        <geom name="aux_1_geom" type="capsule" size="0.08" fromto="0.0 0.0 0.0 0.4 0.4 0.0" />
        <body name="aux_1" pos="0.4 0.4 0">
          <joint name="hip_1" type="hinge" pos="0.0 0.0 0.0" axis="0 0 1" range="-30 30" />
          <geom name="left_leg_geom" type="capsule" size="0.08" fromto="0.0 0.0 0.0 0.4 0.4 0.0" />
          <body pos="0.4 0.4 0">
            <joint name="ankle_1" type="hinge" pos="0.0 0.0 0.0" axis="-1 1 0" range="30 70" />
            <geom name="left_ankle_geom" type="capsule" size="0.08" fromto="0.0 0.0 0.0 0.4 0.4 0.0" />
          </body>
        </body>
      </body>
      <body name="front_right_leg" pos="0 0 0">
        <geom name="aux_2_geom" type="capsule" size="0.08" fromto="0.0 0.0 0.0 -0.4 0.4 0.0" />
        <body name="aux_2" pos="-0.4 0.4 0">
          <joint name="hip_2" type="hinge" pos="0.0 0.0 0.0" axis="0 0 1" range="-30 30" />
          <geom name="right_leg_geom" type="capsule" size="0.08" fromto="0.0 0.0 0.0 -0.4 0.4 0.0" />
          <body pos="-0.4 0.4 0">
            <joint name="ankle_2" type="hinge" pos="0.0 0.0 0.0" axis="1 1 0" range="-70 -30" />
            <geom name="right_ankle_geom" type="capsule" size="0.08" fromto="0.0 0.0 0.0 -0.4 0.4 0.0" />
          </body>
        </body>
      </body>
      <body name="back_leg" pos="0 0 0">
        <geom name="aux_3_geom" type="capsule" size="0.08" fromto="0.0 0.0 0.0 -0.4 -0.4 0.0" />
        <body name="aux_3" pos="-0.4 -0.4 0">
          <joint name="hip_3" type="hinge" pos="0.0 0.0 0.0" axis="0 0 1" range="-30 30" />
          <geom name="back_leg_geom" type="capsule" size="0.08" fromto="0.0 0.0 0.0 -0.4 -0.4 0.0" />
          <body pos="-0.4 -0.4 0">
            <joint name="ankle_3" type="hinge" pos="0.0 0.0 0.0" axis="-1 1 0" range="-70 -30" />
            <geom name="third_ankle_geom" type="capsule" size="0.08" fromto="0.0 0.0 0.0 -0.4 -0.4 0.0" />
          </body>
        </body>
      </body>
      <body name="right_back_leg" pos="0 0 0">
        <geom name="aux_4_geom" type="capsule" size="0.08" fromto="0.0 0.0 0.0 0.4 -0.4 0.0" />
        <body name="aux_4" pos="0.4 -0.4 0">
          <joint name="hip_4" type="hinge" pos="0.0 0.0 0.0" axis="0 0 1" range="-30 30" />
          <geom name="rightback_leg_geom" type="capsule" size="0.08" fromto="0.0 0.0 0.0 0.4 -0.4 0.0" />
          <body pos="0.4 -0.4 0">
            <joint name="ankle_4" type="hinge" pos="0.0 0.0 0.0" axis="1 1 0" range="30 70" />
            <geom name="fourth_ankle_geom" type="capsule" size="0.08" fromto="0.0 0.0 0.0 0.4 -0.4 0.0" />
          </body>
        </body>
      </body>
    </body>
    <body name="skybox" pos="0.8 0.75 0">
      <site name="target0" pos="2 2 1" size="0.7" rgba="1 0 0 1" type="sphere"></site>
      <site name = "subgoal_0" type="sphere" pos="0 0 0.5" size="0.7" rgba="1 0 1 0" /><!-- Subgoal 1: Purple -->
      <site name = "subgoal_1" type="sphere" pos="0 0 0.5" size="0.7" rgba="0 1 0 0" /><!-- Subgoal 2: Green -->
      <site name = "subgoal_2" type="sphere" pos="0 0 0.5" size="0.7" rgba="0.5 0.5 0.5 0" /><!-- Subgoal 3: Gray -->
      <site name = "subgoal_3" type="sphere" pos="0 0 0.5" size="0.7" rgba="1 1 1 0" /><!-- Subgoal 4: White -->
      <site name = "subgoal_4" type="sphere" pos="0 0 0.5" size="0.7" rgba="0 0 0 0" /><!-- Subgoal 5: Black -->
    </body>
    <!-- <include file="maze_blocks.xml"></include> -->
  </worldbody>
  <actuator>
    <motor joint="hip_1" ctrlrange="-1.0 1.0" gear="100.0" ctrllimited="true" />
    <motor joint="hip_2" ctrlrange="-1.0 1.0" gear="100.0" ctrllimited="true" />
    <motor joint="hip_3" ctrlrange="-1.0 1.0" gear="100.0" ctrllimited="true" />
    <motor joint="hip_4" ctrlrange="-1.0 1.0" gear="100.0" ctrllimited="true" />
    <motor joint="ankle_4" ctrlrange="-1.0 1.0" gear="100.0" ctrllimited="true" />
    <motor joint="ankle_1" ctrlrange="-1.0 1.0" gear="100.0" ctrllimited="true" />
    <motor joint="ankle_2" ctrlrange="-1.0 1.0" gear="100.0" ctrllimited="true" />
    <motor joint="ankle_3" ctrlrange="-1.0 1.0" gear="100.0" ctrllimited="true" />
  </actuator>
</mujoco>
