<mujoco>
  <compiler inertiafromgeom="true" angle="degree" coordinate="local" />
  <size njmax="5000" nconmax="3500"></size>
  <option timestep="0.01" integrator="RK4" />
  <default>
    <joint limited="false" armature="0" damping="0" />
    <geom condim="3" conaffinity="0" margin="0" friction="1 0.5 0.5" rgba="0.8 0.6 0.4 1" density="100" />
  </default>
  <asset>
    <texture type="skybox" builtin="gradient" width="100" height="100" rgb1="1 1 1" rgb2="0 0 0" />
    <texture name="texgeom" type="cube" builtin="flat" mark="cross" width="127" height="1278" rgb1="0.8 0.6 0.4" rgb2="0.8 0.6 0.4" markrgb="1 1 1" random="0.01" />
    <texture name="texplane" type="2d" builtin="checker" rgb1="0.2 0.3 0.4" rgb2="0.1 0.2 0.3" width="100" height="100" />
    <material name='MatPlane' texture="texplane" shininess="1" texrepeat="30 30" specular="1"  reflectance="0.0" />
    <material name='geom' texture="texgeom" texuniform="true" />
  </asset>
  <worldbody>
    <light directional="true" cutoff="100" exponent="1" diffuse="1 1 1" specular=".1 .1 .1" pos="0 0 1.3" dir="-0 0 -1.3" />
    <geom name='floor' pos='0 0 0' size='40 40 40' type='plane' conaffinity='1' rgba='0.8 0.9 0.8 1' condim='3' material='MatPlane' />
    <body name="torso" pos="0 0 0">
      <geom name="pointbody" type="sphere" size="0.6" pos="0 0 1.0" />
      <geom name="pointarrow" type="box" size="0.6 0.1 0.1" pos="0.6 0 1.0" />
      <joint name='ballx' type='slide' axis='1 0 0' pos='0 0 0' />
      <joint name='bally' type='slide' axis='0 1 0' pos='0 0 0' />
      <joint name='rot' type='hinge' axis='0 0 1' pos='0 0 0' limited="false" />
    </body>
    <body name="skybox" pos="0.8 0.75 0">
      <site name="target0" pos="2 2 1" size="0.7" rgba="1 0 0 1" type="sphere"></site>
      <site name = "subgoal_0" type="sphere" pos="0 0 0.5" size="0.7" rgba="1 0 1 0" /><!-- Subgoal 1: Purple -->
      <site name = "subgoal_1" type="sphere" pos="0 0 0.5" size="0.7" rgba="0 1 0 0" /><!-- Subgoal 2: Green -->
      <site name = "subgoal_2" type="sphere" pos="0 0 0.5" size="0.7" rgba="0.5 0.5 0.5 0" /><!-- Subgoal 3: Gray -->
      <site name = "subgoal_3" type="sphere" pos="0 0 0.5" size="0.7" rgba="1 1 1 0" /><!-- Subgoal 4: White -->
      <site name = "subgoal_4" type="sphere" pos="0 0 0.5" size="0.7" rgba="0 0 0 0" /><!-- Subgoal 5: Black -->
    </body>
    <!-- <include file="maze_blocks.xml"></include> -->
  </worldbody>
  <actuator>
    <motor joint='ballx' ctrlrange="-1 1" ctrllimited="true" gear="1.0" />
    <motor joint='rot' ctrlrange="-1 1" ctrllimited="true" gear="0.25" />
  </actuator>
</mujoco>
