<mujoco model="ant">
  <compiler angle="degree" coordinate="local" inertiafromgeom="true" />
  <size nconmax="3500" njmax="5000" />
  <option integrator="RK4" timestep="0.01" />
  <custom>
    <numeric data="0.0 0.0 0.55 1.0 0.0 0.0 0.0 0.0 1.0 0.0 -1.0 0.0 -1.0 0.0 1.0" name="init_qpos" />
  </custom>
  <default>
    <joint armature="1" damping="1" limited="true" />
    <geom conaffinity="0" condim="3" density="5.0" friction="1 0.5 0.5" margin="0.01" rgba="0.8 0.6 0.4 1" solimp=".8 .8 .01" solref=".02 1" />
  </default>
  <asset>
    <texture builtin="gradient" height="100" rgb1="1 1 1" rgb2="0 0 0" type="skybox" width="100" />
    <texture builtin="flat" height="1278" mark="cross" markrgb="1 1 1" name="texgeom" random="0.01" rgb1="0.8 0.6 0.4" rgb2="0.8 0.6 0.4" type="cube" width="127" />
    <texture builtin="checker" height="100" name="texplane" rgb1="0.2 0.3 0.4" rgb2="0.1 0.2 0.3" type="2d" width="100" />
    <material name="MatPlane" reflectance="0.0" shininess="1" specular="1" texrepeat="60 60" texture="texplane" />
    <material name="geom" texture="texgeom" texuniform="true" />
  </asset>
  <worldbody>
    <light cutoff="100" diffuse="1 1 1" dir="-0 0 -1.3" directional="true" exponent="1" pos="0 0 1.3" specular=".1 .1 .1" />
    
    <geom conaffinity="1" condim="3" material="MatPlane" name="floor" pos="0 0 0" rgba="0.8 0.9 0.8 1" size="40 40 40" type="plane" />
    <body name="torso" pos="0 0 0.75">
      <geom name="torso_geom" pos="0 0 0" rgba="0.3 0.9 0.5 1" size="0.4" type="sphere" />
      <joint armature="0" axis="0 0 1" damping="0" limited="false" margin="0.01" name="root" pos="0 0 0" type="free" />
      <body name="front_left_leg" pos="0 0 0">
        <geom fromto="0.0 0.0 0.0 0.4 0.4 0.0" name="aux_1_geom" size="0.08" type="capsule" />
        <body name="aux_1" pos="0.4 0.4 0">
          <joint axis="0 0 1" name="hip_1" pos="0.0 0.0 0.0" range="-30 30" type="hinge" />
          <geom fromto="0.0 0.0 0.0 0.4 0.4 0.0" name="left_leg_geom" size="0.08" type="capsule" />
          <body pos="0.4 0.4 0">
            <joint axis="-1 1 0" name="ankle_1" pos="0.0 0.0 0.0" range="30 70" type="hinge" />
            <geom fromto="0.0 0.0 0.0 0.4 0.4 0.0" name="left_ankle_geom" size="0.08" type="capsule" />
          </body>
        </body>
      </body>
      <body name="front_right_leg" pos="0 0 0">
        <geom fromto="0.0 0.0 0.0 -0.4 0.4 0.0" name="aux_2_geom" size="0.08" type="capsule" />
        <body name="aux_2" pos="-0.4 0.4 0">
          <joint axis="0 0 1" name="hip_2" pos="0.0 0.0 0.0" range="-30 30" type="hinge" />
          <geom fromto="0.0 0.0 0.0 -0.4 0.4 0.0" name="right_leg_geom" size="0.08" type="capsule" />
          <body pos="-0.4 0.4 0">
            <joint axis="1 1 0" name="ankle_2" pos="0.0 0.0 0.0" range="-70 -30" type="hinge" />
            <geom fromto="0.0 0.0 0.0 -0.4 0.4 0.0" name="right_ankle_geom" size="0.08" type="capsule" />
          </body>
        </body>
      </body>
      <body name="back_leg" pos="0 0 0">
        <geom fromto="0.0 0.0 0.0 -0.4 -0.4 0.0" name="aux_3_geom" size="0.08" type="capsule" />
        <body name="aux_3" pos="-0.4 -0.4 0">
          <joint axis="0 0 1" name="hip_3" pos="0.0 0.0 0.0" range="-30 30" type="hinge" />
          <geom fromto="0.0 0.0 0.0 -0.4 -0.4 0.0" name="back_leg_geom" size="0.08" type="capsule" />
          <body pos="-0.4 -0.4 0">
            <joint axis="-1 1 0" name="ankle_3" pos="0.0 0.0 0.0" range="-70 -30" type="hinge" />
            <geom fromto="0.0 0.0 0.0 -0.4 -0.4 0.0" name="third_ankle_geom" size="0.08" type="capsule" />
          </body>
        </body>
      </body>
      <body name="right_back_leg" pos="0 0 0">
        <geom fromto="0.0 0.0 0.0 0.4 -0.4 0.0" name="aux_4_geom" size="0.08" type="capsule" />
        <body name="aux_4" pos="0.4 -0.4 0">
          <joint axis="0 0 1" name="hip_4" pos="0.0 0.0 0.0" range="-30 30" type="hinge" />
          <geom fromto="0.0 0.0 0.0 0.4 -0.4 0.0" name="rightback_leg_geom" size="0.08" type="capsule" />
          <body pos="0.4 -0.4 0">
            <joint axis="1 1 0" name="ankle_4" pos="0.0 0.0 0.0" range="30 70" type="hinge" />
            <geom fromto="0.0 0.0 0.0 0.4 -0.4 0.0" name="fourth_ankle_geom" size="0.08" type="capsule" />
          </body>
        </body>
      </body>
    </body>
    <body name="skybox" pos="0.8 0.75 0">
      <site name="target0" pos="2 2 1" rgba="1 0 0 1" size="0.7" type="sphere" />
      <site name="subgoal_0" pos="0 0 0.5" rgba="1 0 1 0" size="0.7" type="sphere" />
      <site name="subgoal_1" pos="0 0 0.5" rgba="0 1 0 0" size="0.7" type="sphere" />
      <site name="subgoal_2" pos="0 0 0.5" rgba="0.5 0.5 0.5 0" size="0.7" type="sphere" />
      <site name="subgoal_3" pos="0 0 0.5" rgba="1 1 1 0" size="0.7" type="sphere" />
      <site name="subgoal_4" pos="0 0 0.5" rgba="0 0 0 0" size="0.7" type="sphere" />
    </body>
    
  <geom material="" name="object_0_0" pos="-15.000000 12.500000 0.625000" rgba="0.7 0.5 0.3 1.0" size="1.250000 1.250000 1.250000" type="box" /><geom material="" name="object_0_1" pos="-12.500000 12.500000 0.625000" rgba="0.7 0.5 0.3 1.0" size="1.250000 1.250000 1.250000" type="box" /><geom material="" name="object_0_2" pos="-10.000000 12.500000 0.625000" rgba="0.7 0.5 0.3 1.0" size="1.250000 1.250000 1.250000" type="box" /><geom material="" name="object_0_3" pos="-7.500000 12.500000 0.625000" rgba="0.7 0.5 0.3 1.0" size="1.250000 1.250000 1.250000" type="box" /><geom material="" name="object_0_4" pos="-5.000000 12.500000 0.625000" rgba="0.7 0.5 0.3 1.0" size="1.250000 1.250000 1.250000" type="box" /><geom material="" name="object_0_5" pos="-2.500000 12.500000 0.625000" rgba="0.7 0.5 0.3 1.0" size="1.250000 1.250000 1.250000" type="box" /><geom material="" name="object_0_6" pos="0.000000 12.500000 0.625000" rgba="0.7 0.5 0.3 1.0" size="1.250000 1.250000 1.250000" type="box" /><geom material="" name="object_0_7" pos="2.500000 12.500000 0.625000" rgba="0.7 0.5 0.3 1.0" size="1.250000 1.250000 1.250000" type="box" /><geom material="" name="object_0_8" pos="5.000000 12.500000 0.625000" rgba="0.7 0.5 0.3 1.0" size="1.250000 1.250000 1.250000" type="box" /><geom material="" name="object_0_9" pos="7.500000 12.500000 0.625000" rgba="0.7 0.5 0.3 1.0" size="1.250000 1.250000 1.250000" type="box" /><geom material="" name="object_0_10" pos="10.000000 12.500000 0.625000" rgba="0.7 0.5 0.3 1.0" size="1.250000 1.250000 1.250000" type="box" /><geom material="" name="object_0_11" pos="12.500000 12.500000 0.625000" rgba="0.7 0.5 0.3 1.0" size="1.250000 1.250000 1.250000" type="box" /><geom material="" name="object_0_12" pos="15.000000 12.500000 0.625000" rgba="0.7 0.5 0.3 1.0" size="1.250000 1.250000 1.250000" type="box" /><geom material="" name="object_1_0" pos="-15.000000 10.000000 0.625000" rgba="0.7 0.5 0.3 1.0" size="1.250000 1.250000 1.250000" type="box" /><geom material="" name="object_1_6" pos="0.000000 10.000000 0.625000" rgba="0.7 0.5 0.3 1.0" size="1.250000 1.250000 1.250000" type="box" /><geom material="" name="object_1_12" pos="15.000000 10.000000 0.625000" rgba="0.7 0.5 0.3 1.0" size="1.250000 1.250000 1.250000" type="box" /><geom material="" name="object_2_0" pos="-15.000000 7.500000 0.625000" rgba="0.7 0.5 0.3 1.0" size="1.250000 1.250000 1.250000" type="box" /><geom material="" name="object_2_12" pos="15.000000 7.500000 0.625000" rgba="0.7 0.5 0.3 1.0" size="1.250000 1.250000 1.250000" type="box" /><geom material="" name="object_3_0" pos="-15.000000 5.000000 0.625000" rgba="0.7 0.5 0.3 1.0" size="1.250000 1.250000 1.250000" type="box" /><geom material="" name="object_3_12" pos="15.000000 5.000000 0.625000" rgba="0.7 0.5 0.3 1.0" size="1.250000 1.250000 1.250000" type="box" /><geom material="" name="object_4_0" pos="-15.000000 2.500000 0.625000" rgba="0.7 0.5 0.3 1.0" size="1.250000 1.250000 1.250000" type="box" /><geom material="" name="object_4_6" pos="0.000000 2.500000 0.625000" rgba="0.7 0.5 0.3 1.0" size="1.250000 1.250000 1.250000" type="box" /><geom material="" name="object_4_12" pos="15.000000 2.500000 0.625000" rgba="0.7 0.5 0.3 1.0" size="1.250000 1.250000 1.250000" type="box" /><geom material="" name="object_5_0" pos="-15.000000 0.000000 0.625000" rgba="0.7 0.5 0.3 1.0" size="1.250000 1.250000 1.250000" type="box" /><geom material="" name="object_5_6" pos="0.000000 0.000000 0.625000" rgba="0.7 0.5 0.3 1.0" size="1.250000 1.250000 1.250000" type="box" /><geom material="" name="object_5_12" pos="15.000000 0.000000 0.625000" rgba="0.7 0.5 0.3 1.0" size="1.250000 1.250000 1.250000" type="box" /><geom material="" name="object_6_0" pos="-15.000000 -2.500000 0.625000" rgba="0.7 0.5 0.3 1.0" size="1.250000 1.250000 1.250000" type="box" /><geom material="" name="object_6_1" pos="-12.500000 -2.500000 0.625000" rgba="0.7 0.5 0.3 1.0" size="1.250000 1.250000 1.250000" type="box" /><geom material="" name="object_6_2" pos="-10.000000 -2.500000 0.625000" rgba="0.7 0.5 0.3 1.0" size="1.250000 1.250000 1.250000" type="box" /><geom material="" name="object_6_6" pos="0.000000 -2.500000 0.625000" rgba="0.7 0.5 0.3 1.0" size="1.250000 1.250000 1.250000" type="box" /><geom material="" name="object_6_10" pos="10.000000 -2.500000 0.625000" rgba="0.7 0.5 0.3 1.0" size="1.250000 1.250000 1.250000" type="box" /><geom material="" name="object_6_11" pos="12.500000 -2.500000 0.625000" rgba="0.7 0.5 0.3 1.0" size="1.250000 1.250000 1.250000" type="box" /><geom material="" name="object_6_12" pos="15.000000 -2.500000 0.625000" rgba="0.7 0.5 0.3 1.0" size="1.250000 1.250000 1.250000" type="box" /><geom material="" name="object_7_0" pos="-15.000000 -5.000000 0.625000" rgba="0.7 0.5 0.3 1.0" size="1.250000 1.250000 1.250000" type="box" /><geom material="" name="object_7_6" pos="0.000000 -5.000000 0.625000" rgba="0.7 0.5 0.3 1.0" size="1.250000 1.250000 1.250000" type="box" /><geom material="" name="object_7_12" pos="15.000000 -5.000000 0.625000" rgba="0.7 0.5 0.3 1.0" size="1.250000 1.250000 1.250000" type="box" /><geom material="" name="object_8_0" pos="-15.000000 -7.500000 0.625000" rgba="0.7 0.5 0.3 1.0" size="1.250000 1.250000 1.250000" type="box" /><geom material="" name="object_8_12" pos="15.000000 -7.500000 0.625000" rgba="0.7 0.5 0.3 1.0" size="1.250000 1.250000 1.250000" type="box" /><geom material="" name="object_9_0" pos="-15.000000 -10.000000 0.625000" rgba="0.7 0.5 0.3 1.0" size="1.250000 1.250000 1.250000" type="box" /><geom material="" name="object_9_12" pos="15.000000 -10.000000 0.625000" rgba="0.7 0.5 0.3 1.0" size="1.250000 1.250000 1.250000" type="box" /><geom material="" name="object_10_0" pos="-15.000000 -12.500000 0.625000" rgba="0.7 0.5 0.3 1.0" size="1.250000 1.250000 1.250000" type="box" /><geom material="" name="object_10_6" pos="0.000000 -12.500000 0.625000" rgba="0.7 0.5 0.3 1.0" size="1.250000 1.250000 1.250000" type="box" /><geom material="" name="object_10_12" pos="15.000000 -12.500000 0.625000" rgba="0.7 0.5 0.3 1.0" size="1.250000 1.250000 1.250000" type="box" /><geom material="" name="object_11_0" pos="-15.000000 -15.000000 0.625000" rgba="0.7 0.5 0.3 1.0" size="1.250000 1.250000 1.250000" type="box" /><geom material="" name="object_11_1" pos="-12.500000 -15.000000 0.625000" rgba="0.7 0.5 0.3 1.0" size="1.250000 1.250000 1.250000" type="box" /><geom material="" name="object_11_2" pos="-10.000000 -15.000000 0.625000" rgba="0.7 0.5 0.3 1.0" size="1.250000 1.250000 1.250000" type="box" /><geom material="" name="object_11_3" pos="-7.500000 -15.000000 0.625000" rgba="0.7 0.5 0.3 1.0" size="1.250000 1.250000 1.250000" type="box" /><geom material="" name="object_11_4" pos="-5.000000 -15.000000 0.625000" rgba="0.7 0.5 0.3 1.0" size="1.250000 1.250000 1.250000" type="box" /><geom material="" name="object_11_5" pos="-2.500000 -15.000000 0.625000" rgba="0.7 0.5 0.3 1.0" size="1.250000 1.250000 1.250000" type="box" /><geom material="" name="object_11_6" pos="0.000000 -15.000000 0.625000" rgba="0.7 0.5 0.3 1.0" size="1.250000 1.250000 1.250000" type="box" /><geom material="" name="object_11_7" pos="2.500000 -15.000000 0.625000" rgba="0.7 0.5 0.3 1.0" size="1.250000 1.250000 1.250000" type="box" /><geom material="" name="object_11_8" pos="5.000000 -15.000000 0.625000" rgba="0.7 0.5 0.3 1.0" size="1.250000 1.250000 1.250000" type="box" /><geom material="" name="object_11_9" pos="7.500000 -15.000000 0.625000" rgba="0.7 0.5 0.3 1.0" size="1.250000 1.250000 1.250000" type="box" /><geom material="" name="object_11_10" pos="10.000000 -15.000000 0.625000" rgba="0.7 0.5 0.3 1.0" size="1.250000 1.250000 1.250000" type="box" /><geom material="" name="object_11_11" pos="12.500000 -15.000000 0.625000" rgba="0.7 0.5 0.3 1.0" size="1.250000 1.250000 1.250000" type="box" /><geom material="" name="object_11_12" pos="15.000000 -15.000000 0.625000" rgba="0.7 0.5 0.3 1.0" size="1.250000 1.250000 1.250000" type="box" /></worldbody>
  <actuator>
    <motor ctrllimited="true" ctrlrange="-1.0 1.0" gear="100.0" joint="hip_1" />
    <motor ctrllimited="true" ctrlrange="-1.0 1.0" gear="100.0" joint="hip_2" />
    <motor ctrllimited="true" ctrlrange="-1.0 1.0" gear="100.0" joint="hip_3" />
    <motor ctrllimited="true" ctrlrange="-1.0 1.0" gear="100.0" joint="hip_4" />
    <motor ctrllimited="true" ctrlrange="-1.0 1.0" gear="100.0" joint="ankle_4" />
    <motor ctrllimited="true" ctrlrange="-1.0 1.0" gear="100.0" joint="ankle_1" />
    <motor ctrllimited="true" ctrlrange="-1.0 1.0" gear="100.0" joint="ankle_2" />
    <motor ctrllimited="true" ctrlrange="-1.0 1.0" gear="100.0" joint="ankle_3" />
  </actuator>
</mujoco>